I'm sorry, but an uncaught exception occurred.

While running game code:
  File "game/script.rpy", line 237, in script
    ph "Brrr....Brrr..."
Exception: Sayer 'ph' is not defined.

-- Full Traceback ------------------------------------------------------------

Full traceback:
  File "game/script.rpy", line 237, in script
    ph "Brrr....Brrr..."
  File "C:\Renpy\renpy-7.3.5-sdk\renpy\ast.py", line 678, in execute
    who = eval_who(self.who, self.who_fast)
  File "C:\Renpy\renpy-7.3.5-sdk\renpy\ast.py", line 576, in eval_who
    raise Exception("Sayer '%s' is not defined." % who.encode("utf-8"))
Exception: Sayer 'ph' is not defined.

Windows-8-6.2.9200
Ren'Py 7.3.5.606
TentativeName 1.0
Wed Aug 12 17:17:49 2020
